Traceback (most recent call last):
  File "C:\Users\a1233249\.conda\envs\book\Lib\site-packages\jupyter_cache\executors\utils.py", line 58, in single_nb_execution
    executenb(
  File "C:\Users\a1233249\.conda\envs\book\Lib\site-packages\nbclient\client.py", line 1305, in execute
    return NotebookClient(nb=nb, resources=resources, km=km, **kwargs).execute()
           ^^^^^^^^^^^^^^^^^^^^^^^^^^^^^^^^^^^^^^^^^^^^^^^^^^^^^^^^^^^^^^^^^^^^^
  File "C:\Users\a1233249\.conda\envs\book\Lib\site-packages\jupyter_core\utils\__init__.py", line 165, in wrapped
    return loop.run_until_complete(inner)
           ^^^^^^^^^^^^^^^^^^^^^^^^^^^^^^
  File "C:\Users\a1233249\.conda\envs\book\Lib\asyncio\base_events.py", line 685, in run_until_complete
    return future.result()
           ^^^^^^^^^^^^^^^
  File "C:\Users\a1233249\.conda\envs\book\Lib\site-packages\nbclient\client.py", line 705, in async_execute
    await self.async_execute_cell(
  File "C:\Users\a1233249\.conda\envs\book\Lib\site-packages\nbclient\client.py", line 1058, in async_execute_cell
    await self._check_raise_for_error(cell, cell_index, exec_reply)
  File "C:\Users\a1233249\.conda\envs\book\Lib\site-packages\nbclient\client.py", line 914, in _check_raise_for_error
    raise CellExecutionError.from_cell_and_msg(cell, exec_reply_content)
nbclient.exceptions.CellExecutionError: An error occurred while executing the following cell:
------------------
# Load the image
# Note: Image will have georeferencing error because it does gone through georeferencing yet which is normally done after reflectance.
imgFile = rasterio.open('img_radiance', 'r')

# Loading Metadata Data
data_anc = np.load('img_metadata.npz')
print('Ancillary data associated with this file: ' + str(data_anc.files))

# Set some of the variables from the ancillary data
wave = data_anc['wavelengths']
rgb_index = data_anc['rgb_index']
rgb_image = data_anc['rgb_image']

# Display Red/Green/Blue or true color image
plt.figure(figsize=(10,10))
plt.imshow(rgb_image)
------------------


[1;31m---------------------------------------------------------------------------[0m
[1;31mCPLE_OpenFailedError[0m                      Traceback (most recent call last)
File [1;32mrasterio\\_base.pyx:310[0m, in [0;36mrasterio._base.DatasetBase.__init__[1;34m()[0m

File [1;32mrasterio\\_base.pyx:221[0m, in [0;36mrasterio._base.open_dataset[1;34m()[0m

File [1;32mrasterio\\_err.pyx:221[0m, in [0;36mrasterio._err.exc_wrap_pointer[1;34m()[0m

[1;31mCPLE_OpenFailedError[0m: img_radiance: No such file or directory

During handling of the above exception, another exception occurred:

[1;31mRasterioIOError[0m                           Traceback (most recent call last)
Cell [1;32mIn[2], line 3[0m
[0;32m      1[0m [38;5;66;03m# Load the image[39;00m
[0;32m      2[0m [38;5;66;03m# Note: Image will have georeferencing error because it does gone through georeferencing yet which is normally done after reflectance.[39;00m
[1;32m----> 3[0m imgFile [38;5;241m=[39m [43mrasterio[49m[38;5;241;43m.[39;49m[43mopen[49m[43m([49m[38;5;124;43m'[39;49m[38;5;124;43mimg_radiance[39;49m[38;5;124;43m'[39;49m[43m,[49m[43m [49m[38;5;124;43m'[39;49m[38;5;124;43mr[39;49m[38;5;124;43m'[39;49m[43m)[49m
[0;32m      5[0m [38;5;66;03m# Loading Metadata Data[39;00m
[0;32m      6[0m data_anc [38;5;241m=[39m np[38;5;241m.[39mload([38;5;124m'[39m[38;5;124mimg_metadata.npz[39m[38;5;124m'[39m)

File [1;32m~\.conda\envs\book\Lib\site-packages\rasterio\env.py:451[0m, in [0;36mensure_env_with_credentials.<locals>.wrapper[1;34m(*args, **kwds)[0m
[0;32m    448[0m     session [38;5;241m=[39m DummySession()
[0;32m    450[0m [38;5;28;01mwith[39;00m env_ctor(session[38;5;241m=[39msession):
[1;32m--> 451[0m     [38;5;28;01mreturn[39;00m [43mf[49m[43m([49m[38;5;241;43m*[39;49m[43margs[49m[43m,[49m[43m [49m[38;5;241;43m*[39;49m[38;5;241;43m*[39;49m[43mkwds[49m[43m)[49m

File [1;32m~\.conda\envs\book\Lib\site-packages\rasterio\__init__.py:317[0m, in [0;36mopen[1;34m(fp, mode, driver, width, height, count, crs, transform, dtype, nodata, sharing, **kwargs)[0m
[0;32m    314[0m path [38;5;241m=[39m _parse_path(raw_dataset_path)
[0;32m    316[0m [38;5;28;01mif[39;00m mode [38;5;241m==[39m [38;5;124m"[39m[38;5;124mr[39m[38;5;124m"[39m:
[1;32m--> 317[0m     dataset [38;5;241m=[39m [43mDatasetReader[49m[43m([49m[43mpath[49m[43m,[49m[43m [49m[43mdriver[49m[38;5;241;43m=[39;49m[43mdriver[49m[43m,[49m[43m [49m[43msharing[49m[38;5;241;43m=[39;49m[43msharing[49m[43m,[49m[43m [49m[38;5;241;43m*[39;49m[38;5;241;43m*[39;49m[43mkwargs[49m[43m)[49m
[0;32m    318[0m [38;5;28;01melif[39;00m mode [38;5;241m==[39m [38;5;124m"[39m[38;5;124mr+[39m[38;5;124m"[39m:
[0;32m    319[0m     dataset [38;5;241m=[39m get_writer_for_path(path, driver[38;5;241m=[39mdriver)(
[0;32m    320[0m         path, mode, driver[38;5;241m=[39mdriver, sharing[38;5;241m=[39msharing, [38;5;241m*[39m[38;5;241m*[39mkwargs
[0;32m    321[0m     )

File [1;32mrasterio\\_base.pyx:312[0m, in [0;36mrasterio._base.DatasetBase.__init__[1;34m()[0m

[1;31mRasterioIOError[0m: img_radiance: No such file or directory

