Traceback (most recent call last):
  File "C:\Users\a1233249\.conda\envs\book\Lib\site-packages\jupyter_cache\executors\utils.py", line 58, in single_nb_execution
    executenb(
  File "C:\Users\a1233249\.conda\envs\book\Lib\site-packages\nbclient\client.py", line 1305, in execute
    return NotebookClient(nb=nb, resources=resources, km=km, **kwargs).execute()
           ^^^^^^^^^^^^^^^^^^^^^^^^^^^^^^^^^^^^^^^^^^^^^^^^^^^^^^^^^^^^^^^^^^^^^
  File "C:\Users\a1233249\.conda\envs\book\Lib\site-packages\jupyter_core\utils\__init__.py", line 165, in wrapped
    return loop.run_until_complete(inner)
           ^^^^^^^^^^^^^^^^^^^^^^^^^^^^^^
  File "C:\Users\a1233249\.conda\envs\book\Lib\asyncio\base_events.py", line 685, in run_until_complete
    return future.result()
           ^^^^^^^^^^^^^^^
  File "C:\Users\a1233249\.conda\envs\book\Lib\site-packages\nbclient\client.py", line 705, in async_execute
    await self.async_execute_cell(
  File "C:\Users\a1233249\.conda\envs\book\Lib\site-packages\nbclient\client.py", line 1058, in async_execute_cell
    await self._check_raise_for_error(cell, cell_index, exec_reply)
  File "C:\Users\a1233249\.conda\envs\book\Lib\site-packages\nbclient\client.py", line 914, in _check_raise_for_error
    raise CellExecutionError.from_cell_and_msg(cell, exec_reply_content)
nbclient.exceptions.CellExecutionError: An error occurred while executing the following cell:
------------------
fig, ax = plt.subplots(figsize=(5, 5))
rasterio.plot.show(image_array, ax=ax)
shape.plot(ax=ax, facecolor='none', edgecolor='red')
------------------


[1;31m---------------------------------------------------------------------------[0m
[1;31mNameError[0m                                 Traceback (most recent call last)
Cell [1;32mIn[3], line 3[0m
[0;32m      1[0m fig, ax [38;5;241m=[39m plt[38;5;241m.[39msubplots(figsize[38;5;241m=[39m([38;5;241m5[39m, [38;5;241m5[39m))
[0;32m      2[0m rasterio[38;5;241m.[39mplot[38;5;241m.[39mshow(image_array, ax[38;5;241m=[39max)
[1;32m----> 3[0m [43mshape[49m[38;5;241m.[39mplot(ax[38;5;241m=[39max, facecolor[38;5;241m=[39m[38;5;124m'[39m[38;5;124mnone[39m[38;5;124m'[39m, edgecolor[38;5;241m=[39m[38;5;124m'[39m[38;5;124mred[39m[38;5;124m'[39m)

[1;31mNameError[0m: name 'shape' is not defined

