Traceback (most recent call last):
  File "C:\Users\a1233249\.conda\envs\book\Lib\site-packages\jupyter_cache\executors\utils.py", line 58, in single_nb_execution
    executenb(
  File "C:\Users\a1233249\.conda\envs\book\Lib\site-packages\nbclient\client.py", line 1305, in execute
    return NotebookClient(nb=nb, resources=resources, km=km, **kwargs).execute()
           ^^^^^^^^^^^^^^^^^^^^^^^^^^^^^^^^^^^^^^^^^^^^^^^^^^^^^^^^^^^^^^^^^^^^^
  File "C:\Users\a1233249\.conda\envs\book\Lib\site-packages\jupyter_core\utils\__init__.py", line 165, in wrapped
    return loop.run_until_complete(inner)
           ^^^^^^^^^^^^^^^^^^^^^^^^^^^^^^
  File "C:\Users\a1233249\.conda\envs\book\Lib\asyncio\base_events.py", line 685, in run_until_complete
    return future.result()
           ^^^^^^^^^^^^^^^
  File "C:\Users\a1233249\.conda\envs\book\Lib\site-packages\nbclient\client.py", line 705, in async_execute
    await self.async_execute_cell(
  File "C:\Users\a1233249\.conda\envs\book\Lib\site-packages\nbclient\client.py", line 1058, in async_execute_cell
    await self._check_raise_for_error(cell, cell_index, exec_reply)
  File "C:\Users\a1233249\.conda\envs\book\Lib\site-packages\nbclient\client.py", line 914, in _check_raise_for_error
    raise CellExecutionError.from_cell_and_msg(cell, exec_reply_content)
nbclient.exceptions.CellExecutionError: An error occurred while executing the following cell:
------------------

fig = plt.figure(figsize=(10,7))
gs = GridSpec(nrows=1, ncols=2)

ax0 = fig.add_subplot(gs[:, 0])
ax0.imshow(rgb(Radiance_array))

# Second axes
header = read_header('hsi_data/img_radiance.hdr')
wavelengths=np.asarray(header['wavelength'],dtype='float64')
# ax1 = plt.subplot(gs[0,1])
# ax1 = fig.add_subplot(gs[0, 1])
ax1 = plt.axes([0.50, 0.45, 0.5, 0.3])

# plotting
tarps_radiance=extract_spectra(Radiance_array)
ax1.plot(wavelengths,spectra)
# ax1.set_xticks(ax1.get_xticks()[::25])
# ax1.tick_params(axis='x', labelrotation=45)
plt.ylabel('Radiance (Watts/m2/sr/nm)')
plt.title('Radiance Spectra')
------------------


[1;31m---------------------------------------------------------------------------[0m
[1;31mNameError[0m                                 Traceback (most recent call last)
Cell [1;32mIn[11], line 16[0m
[0;32m     14[0m [38;5;66;03m# plotting[39;00m
[0;32m     15[0m tarps_radiance[38;5;241m=[39mextract_spectra(Radiance_array)
[1;32m---> 16[0m ax1[38;5;241m.[39mplot(wavelengths,[43mspectra[49m)
[0;32m     17[0m [38;5;66;03m# ax1.set_xticks(ax1.get_xticks()[::25])[39;00m
[0;32m     18[0m [38;5;66;03m# ax1.tick_params(axis='x', labelrotation=45)[39;00m
[0;32m     19[0m plt[38;5;241m.[39mylabel([38;5;124m'[39m[38;5;124mRadiance (Watts/m2/sr/nm)[39m[38;5;124m'[39m)

[1;31mNameError[0m: name 'spectra' is not defined

