Traceback (most recent call last):
  File "C:\Users\a1233249\.conda\envs\abc\Lib\site-packages\jupyter_cache\executors\utils.py", line 58, in single_nb_execution
    executenb(
  File "C:\Users\a1233249\.conda\envs\abc\Lib\site-packages\nbclient\client.py", line 1314, in execute
    return NotebookClient(nb=nb, resources=resources, km=km, **kwargs).execute()
           ^^^^^^^^^^^^^^^^^^^^^^^^^^^^^^^^^^^^^^^^^^^^^^^^^^^^^^^^^^^^^^^^^^^^^
  File "C:\Users\a1233249\.conda\envs\abc\Lib\site-packages\jupyter_core\utils\__init__.py", line 165, in wrapped
    return loop.run_until_complete(inner)
           ^^^^^^^^^^^^^^^^^^^^^^^^^^^^^^
  File "C:\Users\a1233249\.conda\envs\abc\Lib\asyncio\base_events.py", line 687, in run_until_complete
    return future.result()
           ^^^^^^^^^^^^^^^
  File "C:\Users\a1233249\.conda\envs\abc\Lib\site-packages\nbclient\client.py", line 709, in async_execute
    await self.async_execute_cell(
  File "C:\Users\a1233249\.conda\envs\abc\Lib\site-packages\nbclient\client.py", line 1062, in async_execute_cell
    await self._check_raise_for_error(cell, cell_index, exec_reply)
  File "C:\Users\a1233249\.conda\envs\abc\Lib\site-packages\nbclient\client.py", line 918, in _check_raise_for_error
    raise CellExecutionError.from_cell_and_msg(cell, exec_reply_content)
nbclient.exceptions.CellExecutionError: An error occurred while executing the following cell:
------------------
import rasterstats as rs
affine=image_array.transform
stats = gpd.GeoDataFrame(rs.zonal_stats(shape, NDVI, affine=affine,stats=["mean"]))
gdf = shape.join(stats)
print(gdf.head())

------------------


[1;31m---------------------------------------------------------------------------[0m
[1;31mModuleNotFoundError[0m                       Traceback (most recent call last)
Cell [1;32mIn[5], line 1[0m
[1;32m----> 1[0m [38;5;28;01mimport[39;00m [38;5;21;01mrasterstats[39;00m [38;5;28;01mas[39;00m [38;5;21;01mrs[39;00m
[0;32m      2[0m affine[38;5;241m=[39mimage_array[38;5;241m.[39mtransform
[0;32m      3[0m stats [38;5;241m=[39m gpd[38;5;241m.[39mGeoDataFrame(rs[38;5;241m.[39mzonal_stats(shape, NDVI, affine[38;5;241m=[39maffine,stats[38;5;241m=[39m[[38;5;124m"[39m[38;5;124mmean[39m[38;5;124m"[39m]))

[1;31mModuleNotFoundError[0m: No module named 'rasterstats'

