Traceback (most recent call last):
  File "C:\Users\a1233249\.conda\envs\book\Lib\site-packages\jupyter_cache\executors\utils.py", line 58, in single_nb_execution
    executenb(
  File "C:\Users\a1233249\.conda\envs\book\Lib\site-packages\nbclient\client.py", line 1305, in execute
    return NotebookClient(nb=nb, resources=resources, km=km, **kwargs).execute()
           ^^^^^^^^^^^^^^^^^^^^^^^^^^^^^^^^^^^^^^^^^^^^^^^^^^^^^^^^^^^^^^^^^^^^^
  File "C:\Users\a1233249\.conda\envs\book\Lib\site-packages\jupyter_core\utils\__init__.py", line 165, in wrapped
    return loop.run_until_complete(inner)
           ^^^^^^^^^^^^^^^^^^^^^^^^^^^^^^
  File "C:\Users\a1233249\.conda\envs\book\Lib\asyncio\base_events.py", line 685, in run_until_complete
    return future.result()
           ^^^^^^^^^^^^^^^
  File "C:\Users\a1233249\.conda\envs\book\Lib\site-packages\nbclient\client.py", line 705, in async_execute
    await self.async_execute_cell(
  File "C:\Users\a1233249\.conda\envs\book\Lib\site-packages\nbclient\client.py", line 1058, in async_execute_cell
    await self._check_raise_for_error(cell, cell_index, exec_reply)
  File "C:\Users\a1233249\.conda\envs\book\Lib\site-packages\nbclient\client.py", line 914, in _check_raise_for_error
    raise CellExecutionError.from_cell_and_msg(cell, exec_reply_content)
nbclient.exceptions.CellExecutionError: An error occurred while executing the following cell:
------------------
import numpy as np
import gpflow
#  GLT coode
import spectral
from spectral import *
import spectral.io.envi as envi
import os
from osgeo import gdal
import os
import glob
from sklearn.model_selection import train_test_split
from sklearn.preprocessing import*
import matplotlib
from gpflow.utilities import print_summary
import pandas as pd
import os
from time import time
import time
import xarray as xa
from matplotlib.pyplot import *
import pdb
from sklearn.preprocessing import *
from sklearn.pipeline import Pipeline
from sklearn.model_selection import train_test_split
from sklearn.metrics import confusion_matrix, accuracy_score, classification_report, cohen_kappa_score
from sklearn.model_selection import RandomizedSearchCV
from sklearn.svm import SVR
from sklearn.svm import SVC
from sklearn.kernel_ridge import KernelRidge
from sklearn.model_selection import cross_val_predict
from sklearn.metrics import *
from sklearn.metrics import mean_squared_error
from sklearn.gaussian_process.kernels import WhiteKernel, ExpSineSquared
from sklearn.metrics.pairwise import polynomial_kernel
from sklearn.metrics.pairwise import rbf_kernel
from sklearn.metrics.pairwise import laplacian_kernel
from sklearn.metrics import mean_absolute_error
from sklearn.metrics import r2_score
from sklearn.model_selection import *
from operator import truediv
import rasterio
from rasterio.plot import show
from rasterio.merge import merge
import pywt 
from scipy.signal import savgol_filter
------------------


[1;31m---------------------------------------------------------------------------[0m
[1;31mModuleNotFoundError[0m                       Traceback (most recent call last)
Cell [1;32mIn[1], line 2[0m
[0;32m      1[0m [38;5;28;01mimport[39;00m [38;5;21;01mnumpy[39;00m [38;5;28;01mas[39;00m [38;5;21;01mnp[39;00m
[1;32m----> 2[0m [38;5;28;01mimport[39;00m [38;5;21;01mgpflow[39;00m
[0;32m      3[0m [38;5;66;03m#  GLT coode[39;00m
[0;32m      4[0m [38;5;28;01mimport[39;00m [38;5;21;01mspectral[39;00m

[1;31mModuleNotFoundError[0m: No module named 'gpflow'

